Workbook

Sheet Overview
A1: FOOTBALL TEAMS | 2026/27
A3: Men's football / Eight domestic league systems + three UEFA competitions / Checked 11 September 2026
A4: START HERE | All Teams is the complete filterable list. Country tabs contain domestic teams only; UEFA has the three league phases.
A6: TEAM-COMPETITION ENTRIES | D6: DOMESTIC ENTRIES | G6: UEFA ENTRIES | J6: COMPETITIONS
A7: =COUNTA('All Teams'!$A$7:$A$785) -> 779 | D7: =COUNTIF('All Teams'!$G$7:$G$785,"Domestic") -> 671 | G7: =COUNTIF('All Teams'!$G$7:$G$785,"UEFA") -> 108 | J7: =COUNTA(Competitions!$B$7:$B$33) -> 27
A10: Counts are competition memberships, not unique clubs: a club may appear domestically and in UEFA. Reserve sides remain separate teams.
A11: DOMESTIC COVERAGE | I11: UEFA LEAGUE PHASE
A12: Country / league system | D12: Tier 1 | E12: Tier 2 | F12: Tier 3 | G12: Total | I12: Competition | L12: Teams
A13: England | D13: =COUNTIFS('All Teams'!$B$7:$B$785,$A13,'All Teams'!$D$7:$D$785,D$23,'All Teams'!$G$7:$G$785,"Domestic") -> 20 | E13: =COUNTIFS('All Teams'!$B$7:$B$785,$A13,'All Teams'!$D$7:$D$785,E$23,'All Teams'!$G$7:$G$785,"Domestic") -> 24 | F13: =COUNTIFS('All Teams'!$B$7:$B$785,$A13,'All Teams'!$D$7:$D$785,F$23,'All Teams'!$G$7:$G$785,"Domestic") -> 24 | G13: =SUM(D13:F13) -> 68 | I13: Champions League | L13: =COUNTIF('All Teams'!$C$7:$C$785,"UEFA Champions League") -> 36
A14: Spain | D14: =COUNTIFS('All Teams'!$B$7:$B$785,$A14,'All Teams'!$D$7:$D$785,D$23,'All Teams'!$G$7:$G$785,"Domestic") -> 20 | E14: =COUNTIFS('All Teams'!$B$7:$B$785,$A14,'All Teams'!$D$7:$D$785,E$23,'All Teams'!$G$7:$G$785,"Domestic") -> 22 | F14: =COUNTIFS('All Teams'!$B$7:$B$785,$A14,'All Teams'!$D$7:$D$785,F$23,'All Teams'!$G$7:$G$785,"Domestic") -> 40 | G14: =SUM(D14:F14) -> 82 | I14: Europa League | L14: =COUNTIF('All Teams'!$C$7:$C$785,"UEFA Europa League") -> 36
A15: Italy | D15: =COUNTIFS('All Teams'!$B$7:$B$785,$A15,'All Teams'!$D$7:$D$785,D$23,'All Teams'!$G$7:$G$785,"Domestic") -> 20 | E15: =COUNTIFS('All Teams'!$B$7:$B$785,$A15,'All Teams'!$D$7:$D$785,E$23,'All Teams'!$G$7:$G$785,"Domestic") -> 20 | F15: =COUNTIFS('All Teams'!$B$7:$B$785,$A15,'All Teams'!$D$7:$D$785,F$23,'All Teams'!$G$7:$G$785,"Domestic") -> 60 | G15: =SUM(D15:F15) -> 100 | I15: Conference League | L15: =COUNTIF('All Teams'!$C$7:$C$785,"UEFA Conference League") -> 36
A16: Germany | D16: =COUNTIFS('All Teams'!$B$7:$B$785,$A16,'All Teams'!$D$7:$D$785,D$23,'All Teams'!$G$7:$G$785,"Domestic") -> 18 | E16: =COUNTIFS('All Teams'!$B$7:$B$785,$A16,'All Teams'!$D$7:$D$785,E$23,'All Teams'!$G$7:$G$785,"Domestic") -> 18 | F16: =COUNTIFS('All Teams'!$B$7:$B$785,$A16,'All Teams'!$D$7:$D$785,F$23,'All Teams'!$G$7:$G$785,"Domestic") -> 20 | G16: =SUM(D16:F16) -> 56 | I16: TOTAL UEFA | L16: =SUM(L13:L15) -> 108
A17: France | D17: =COUNTIFS('All Teams'!$B$7:$B$785,$A17,'All Teams'!$D$7:$D$785,D$23,'All Teams'!$G$7:$G$785,"Domestic") -> 18 | E17: =COUNTIFS('All Teams'!$B$7:$B$785,$A17,'All Teams'!$D$7:$D$785,E$23,'All Teams'!$G$7:$G$785,"Domestic") -> 18 | F17: =COUNTIFS('All Teams'!$B$7:$B$785,$A17,'All Teams'!$D$7:$D$785,F$23,'All Teams'!$G$7:$G$785,"Domestic") -> 18 | G17: =SUM(D17:F17) -> 54
A18: Romania | D18: =COUNTIFS('All Teams'!$B$7:$B$785,$A18,'All Teams'!$D$7:$D$785,D$23,'All Teams'!$G$7:$G$785,"Domestic") -> 16 | E18: =COUNTIFS('All Teams'!$B$7:$B$785,$A18,'All Teams'!$D$7:$D$785,E$23,'All Teams'!$G$7:$G$785,"Domestic") -> 22 | F18: =COUNTIFS('All Teams'!$B$7:$B$785,$A18,'All Teams'!$D$7:$D$785,F$23,'All Teams'!$G$7:$G$785,"Domestic") -> 96 | G18: =SUM(D18:F18) -> 134 | I18: Open Competitions to check expected versus listed team counts for every league.
A19: Greece | D19: =COUNTIFS('All Teams'!$B$7:$B$785,$A19,'All Teams'!$D$7:$D$785,D$23,'All Teams'!$G$7:$G$785,"Domestic") -> 14 | E19: =COUNTIFS('All Teams'!$B$7:$B$785,$A19,'All Teams'!$D$7:$D$785,E$23,'All Teams'!$G$7:$G$785,"Domestic") -> 16 | F19: =COUNTIFS('All Teams'!$B$7:$B$785,$A19,'All Teams'!$D$7:$D$785,F$23,'All Teams'!$G$7:$G$785,"Domestic") -> 113 | G19: =SUM(D19:F19) -> 143
A20: Finland | D20: =COUNTIFS('All Teams'!$B$7:$B$785,$A20,'All Teams'!$D$7:$D$785,D$23,'All Teams'!$G$7:$G$785,"Domestic") -> 12 | E20: =COUNTIFS('All Teams'!$B$7:$B$785,$A20,'All Teams'!$D$7:$D$785,E$23,'All Teams'!$G$7:$G$785,"Domestic") -> 10 | F20: =COUNTIFS('All Teams'!$B$7:$B$785,$A20,'All Teams'!$D$7:$D$785,F$23,'All Teams'!$G$7:$G$785,"Domestic") -> 12 | G20: =SUM(D20:F20) -> 34 | I20: Open Sources for the source register. Every team row also contains its source URL.
A21: TOTAL DOMESTIC | D21: =SUM(D13:D20) -> 138 | E21: =SUM(E13:E20) -> 150 | F21: =SUM(F13:F20) -> 383 | G21: =SUM(G13:G20) -> 671
D23: 1 | E23: 2 | F23: 3
A24: SCOPE AND READING NOTES
A25: SEASONS | D25: 2026/27 for all competitions except Finland's domestic leagues, which use the 2026 calendar-year season.
A27: UEFA | D27: Only the 36 league-phase entrants per competition are listed. Clubs eliminated in qualifying are excluded. UEFA rows cover all associations, not only the eight domestic countries.
A29: THIRD TIERS | D29: Every regional group is included. Group labels are opening-phase allocations; later play-off or continuation splits are not counted as separate leagues. Reserve teams are explicitly labelled.
A31: COUNTRY FIELD | D31: Country means domestic league system or UEFA association, not necessarily geographic location. Cardiff City, Swansea City and Wrexham are under England; FC Andorra is under Spain; Monaco is under France.
A33: SEASON-SPECIFIC NOTES | D33: France's third tier is Ligue 3 (formerly National). Greece's Super League 2 is a unified division. Finland's second and third tiers are Ykkösliiga and Ykkönen.
A35: SNAPSHOT CAUTION | D35: Greek Gamma Ethniki rows are published entrants before the season starts. This is a static snapshot checked on 11 September 2026, not a live feed. Source register labels official and secondary references.
A38: NEW | CLUB COLOUR REFERENCES
A39: Colour names are now appended to All Teams, every country tab and UEFA. The dedicated Club Colours tab provides a compact directory, sources and illustrative HEX values.
A41: DISTINCT TEAMS | D41: BOTH COLOURS | G41: PRIMARY ONLY | J41: NEEDS VERIFICATION
A42: ='Colour Guide'!A7 -> 735 | D42: ='Colour Guide'!D7 -> 567 | G42: ='Colour Guide'!G7 -> 8 | J42: ='Colour Guide'!J7 -> 160
A45: Not all palettes are current or official. Historical references and parent-team inferences are labelled; missing values are left unguessed. Generic swatches are not official club-brand colours.
A47: Open Club Colours: colour-only directory, filters, sources and illustrative HEX codes
A48: Open Colour Guide: coverage by country, evidence types and limitations
A49: Open Colour Sources: source dates, publishers and reference register

Sheet Club Colours
A1: CLUB COLOURS | REFERENCE DIRECTORY
A3: 735 distinct original team names | Colour names + illustrative swatches | Not a current-kit or certified brand-colour database
A4: Open Colour Guide for coverage, definitions and limitations. | Open Overview for the original competition scope.
A6: Team | B6: Country / system | C6: Primary colour | D6: Secondary colour | E6: Primary HEX (illustrative) | F6: Secondary HEX (illustrative) | G6: Coverage | H6: Evidence basis | I6: Colour source ID | J6: Colour source URL | K6: Reference year | L6: Colour notes
A7: AFC Wimbledon | B7: England | C7: Royal blue | D7: Yellow | E7: #2458CE | F7: #FFD633 | G7: Both colours | H7: Club colours reference | I7: C007 | J7: https://en.wikipedia.org/wiki/AFC_Wimbledon
A8: Arsenal | B8: England | C8: Red | D8: White | E8: #D32F2F | F8: #FFFFFF | G8: Both colours | H8: Historical kit reference | I8: C192 | J8: https://www.rsssf.org/colours/england.html | K8: 2006 | L8: Historical reference dated 2006. Traditional home-kit reference; not a 2026/27 kit check.
A9: Aston Villa | B9: England | C9: Claret | D9: Sky blue | E9: #7F1734 | F9: #87CEEB | G9: Both colours | H9: Historical kit reference | I9: C192 | J9: https://www.rsssf.org/colours/england.html | K9: 2006 | L9: Historical reference dated 2006. Traditional home-kit reference; not a 2026/27 kit check.
A10: Barnsley | B10: England | C10: Red | D10: White | E10: #D32F2F | F10: #FFFFFF | G10: Both colours | H10: Historical kit reference | I10: C192 | J10: https://www.rsssf.org/colours/england.html | K10: 2006 | L10: Historical reference dated 2006. Traditional home-kit reference; not a 2026/27 kit check.
A11: Birmingham City | B11: England | C11: Blue | D11: White | E11: #1565C0 | F11: #FFFFFF | G11: Both colours | H11: Historical kit reference | I11: C192 | J11: https://www.rsssf.org/colours/england.html | K11: 2006 | L11: Historical reference dated 2006. Traditional home-kit reference; not a 2026/27 kit check.
A12: Blackburn Rovers | B12: England | C12: Blue | D12: White | E12: #1565C0 | F12: #FFFFFF | G12: Both colours | H12: Historical kit reference | I12: C192 | J12: https://www.rsssf.org/colours/england.html | K12: 2006 | L12: Historical reference dated 2006. Traditional home-kit reference; not a 2026/27 kit check.
A13: Blackpool | B13: England | C13: Tangerine | D13: White | E13: #F28500 | F13: #FFFFFF | G13: Both colours | H13: Historical kit reference | I13: C192 | J13: https://www.rsssf.org/colours/england.html | K13: 2006 | L13: Historical reference dated 2006. Traditional home-kit reference; not a 2026/27 kit check.
A14: Bolton Wanderers | B14: England | C14: White | D14: Navy blue | E14: #FFFFFF | F14: #172B4D | G14: Both colours | H14: Club colours reference | I14: C023 | J14: https://en.wikipedia.org/wiki/Bolton_Wanderers_F.C. | L14: Red is an additional trim colour.
A15: Bournemouth | B15: England | C15: Red | D15: Black | E15: #D32F2F | F15: #111111 | G15: Both colours | H15: Club colours reference | I15: C028 | J15: https://en.wikipedia.org/wiki/AFC_Bournemouth
A16: Bradford City | B16: England | C16: Claret | D16: Amber | E16: #7F1734 | F16: #FFBF00 | G16: Both colours | H16: Historical kit reference | I16: C192 | J16: https://www.rsssf.org/colours/england.html | K16: 2006 | L16: Historical reference dated 2006. Traditional home-kit reference; not a 2026/27 kit check.
A17: Brentford | B17: England | C17: Red | D17: White | E17: #D32F2F | F17: #FFFFFF | G17: Both colours | H17: Club colours reference | I17: C029 | J17: https://en.wikipedia.org/wiki/Brentford_F.C. | L17: Black is an additional traditional kit colour.
A18: Brighton and Hove Albion | B18: England | C18: Blue | D18: White | E18: #1565C0 | F18: #FFFFFF | G18: Both colours | H18: Historical kit reference | I18: C192 | J18: https://www.rsssf.org/colours/england.html | K18: 2006 | L18: Historical reference dated 2006. Traditional home-kit reference; not a 2026/27 kit check.
A19: Bristol City | B19: England | C19: Red | D19: White | E19: #D32F2F | F19: #FFFFFF | G19: Both colours | H19: Historical kit reference | I19: C192 | J19: https://www.rsssf.org/colours/england.html | K19: 2006 | L19: Historical reference dated 2006. Traditional home-kit reference; not a 2026/27 kit check.
A20: Bromley | B20: England | C20: White | D20: Black | E20: #FFFFFF | F20: #111111 | G20: Both colours | H20: Third-party palette reference | I20: C030 | J20: https://teamcolorcodes.com/bromley-f-c-color-codes/ | L20: Traditional white/black pair selected from the published logo palette, which also includes tan and red; not a 2026/27 kit check.
A21: Burnley | B21: England | C21: Claret | D21: Sky blue | E21: #7F1734 | F21: #87CEEB | G21: Both colours | H21: Historical kit reference | I21: C192 | J21: https://www.rsssf.org/colours/england.html | K21: 2006 | L21: Historical reference dated 2006. Traditional home-kit reference; not a 2026/27 kit check.
A22: Burton Albion | B22: England | C22: Yellow | D22: Black | E22: #FFD633 | F22: #111111 | G22: Both colours | H22: Club colours reference | I22: C031 | J22: https://en.wikipedia.org/wiki/Burton_Albion_F.C.
A23: Cambridge United | B23: England | C23: Amber | D23: Black | E23: #FFBF00 | F23: #111111 | G23: Both colours | H23: Club colours reference | I23: C032 | J23: https://en.wikipedia.org/wiki/Cambridge_United_F.C.
A24: Cardiff City | B24: England | C24: Blue | D24: White | E24: #1565C0 | F24: #FFFFFF | G24: Both colours | H24: Historical kit reference | I24: C192 | J24: https://www.rsssf.org/colours/england.html | K24: 2006 | L24: Historical reference dated 2006. Traditional home-kit reference; not a 2026/27 kit check.
A25: Charlton Athletic | B25: England | C25: Red | D25: White | E25: #D32F2F | F25: #FFFFFF | G25: Both colours | H25: Historical kit reference | I25: C192 | J25: https://www.rsssf.org/colours/england.html | K25: 2006 | L25: Historical reference dated 2006. Traditional home-kit reference; not a 2026/27 kit check.
A26: Chelsea | B26: England | C26: Blue | D26: White | E26: #1565C0 | F26: #FFFFFF | G26: Both colours | H26: Historical kit reference | I26: C192 | J26: https://www.rsssf.org/colours/england.html | K26: 2006 | L26: Historical reference dated 2006. Traditional home-kit reference; not a 2026/27 kit check.
A27: Coventry City | B27: England | C27: Sky blue | D27: White | E27: #87CEEB | F27: #FFFFFF | G27: Both colours | H27: Club colours reference | I27: C052 | J27: https://en.wikipedia.org/wiki/Coventry_City_F.C. | L27: White is a traditional accent; sky blue is the defining colour.
A28: Crystal Palace | B28: England | C28: Red | D28: Blue | E28: #D32F2F | F28: #1565C0 | G28: Both colours | H28: Historical kit reference | I28: C192 | J28: https://www.rsssf.org/colours/england.html | K28: 2006 | L28: Historical reference dated 2006. Traditional home-kit reference; not a 2026/27 kit check.
A29: Derby County | B29: England | C29: White | D29: Black | E29: #FFFFFF | F29: #111111 | G29: Both colours | H29: Historical kit reference | I29: C192 | J29: https://www.rsssf.org/colours/england.html | K29: 2006 | L29: Historical reference dated 2006. Traditional home-kit reference; not a 2026/27 kit check.
A30: Doncaster Rovers | B30: England | C30: Red | D30: White | E30: #D32F2F | F30: #FFFFFF | G30: Both colours | H30: Historical kit reference | I30: C192 | J30: https://www.rsssf.org/colours/england.html | K30: 2006 | L30: Historical reference dated 2006. Traditional home-kit reference; not a 2026/27 kit check.
A31: Everton | B31: England | C31: Blue | D31: White | E31: #1565C0 | F31: #FFFFFF | G31: Both colours | H31: Historical kit reference | I31: C192 | J31: https://www.rsssf.org/colours/england.html | K31: 2006 | L31: Historical reference dated 2006. Traditional home-kit reference; not a 2026/27 kit check.
A32: Fulham | B32: England | C32: White | D32: Black | E32: #FFFFFF | F32: #111111 | G32: Both colours | H32: Historical kit reference | I32: C192 | J32: https://www.rsssf.org/colours/england.html | K32: 2006 | L32: Historical reference dated 2006. Traditional home-kit reference; not a 2026/27 kit check.
A33: Huddersfield Town | B33: England | C33: Blue | D33: White | E33: #1565C0 | F33: #FFFFFF | G33: Both colours | H33: Historical kit reference | I33: C192 | J33: https://www.rsssf.org/colours/england.html | K33: 2006 | L33: Historical reference dated 2006. Traditional home-kit reference; not a 2026/27 kit check.
A34: Hull City | B34: England | C34: Amber | D34: Black | E34: #FFBF00 | F34: #111111 | G34: Both colours | H34: Historical kit reference | I34: C192 | J34: https://www.rsssf.org/colours/england.html | K34: 2006 | L34: Historical reference dated 2006. Traditional home-kit reference; not a 2026/27 kit check.
A35: Ipswich Town | B35: England | C35: Blue | D35: White | E35: #1565C0 | F35: #FFFFFF | G35: Both colours | H35: Historical kit reference | I35: C192 | J35: https://www.rsssf.org/colours/england.html | K35: 2006 | L35: Historical reference dated 2006. Traditional home-kit reference; not a 2026/27 kit check.
A36: Leeds United | B36: England | C36: White | D36: Blue | E36: #FFFFFF | F36: #1565C0 | G36: Both colours | H36: Historical kit reference | I36: C192 | J36: https://www.rsssf.org/colours/england.html | K36: 2006 | L36: Historical reference dated 2006. Traditional home-kit reference; not a 2026/27 kit check. Yellow is an additional colour.
A37: Leicester City | B37: England | C37: Blue | D37: White | E37: #1565C0 | F37: #FFFFFF | G37: Both colours | H37: Historical kit reference | I37: C192 | J37: https://www.rsssf.org/colours/england.html | K37: 2006 | L37: Historical reference dated 2006. Traditional home-kit reference; not a 2026/27 kit check.
A38: Leyton Orient | B38: England | C38: Red | D38: White | E38: #D32F2F | F38: #FFFFFF | G38: Both colours | H38: Historical kit reference | I38: C192 | J38: https://www.rsssf.org/colours/england.html | K38: 2006 | L38: Historical reference dated 2006. Traditional home-kit reference; not a 2026/27 kit check.
A39: Lincoln City | B39: England | C39: Red | D39: White | E39: #D32F2F | F39: #FFFFFF | G39: Both colours | H39: Historical kit reference | I39: C192 | J39: https://www.rsssf.org/colours/england.html | K39: 2006 | L39: Historical reference dated 2006. Traditional home-kit reference; not a 2026/27 kit check.
A40: Liverpool | B40: England | C40: Red | D40: White | E40: #D32F2F | F40: #FFFFFF | G40: Both colours | H40: Club colours reference | I40: C144 | J40: https://en.wikipedia.org/wiki/Liverpool_F.C. | L40: White is a historical secondary/accent colour; the usual home strip is all red.
A41: Luton Town | B41: England | C41: Orange | D41: Navy blue | E41: #F28C28 | F41: #172B4D | G41: Both colours | H41: Club colours reference | I41: C148 | J41: https://en.wikipedia.org/wiki/Luton_Town_F.C. | L41: White is an additional club colour.
A42: Manchester City | B42: England | C42: Sky blue | D42: White | E42: #87CEEB | F42: #FFFFFF | G42: Both colours | H42: Historical kit reference | I42: C192 | J42: https://www.rsssf.org/colours/england.html | K42: 2006 | L42: Historical reference dated 2006. Traditional home-kit reference; not a 2026/27 kit check.
...

Sheet Colour Guide
A1: CLUB COLOURS | COVERAGE & GUIDE
A3: Reference colour enrichment of the original workbook. No external account connection or jersey images are required.
A4: Open Club Colours | Filter Coverage for gaps, and Evidence basis for historical or inferred palettes.
A6: DISTINCT TEAMS | D6: BOTH COLOURS | G6: PRIMARY ONLY | J6: NEEDS VERIFICATION
A7: =COUNTA('Club Colours'!$A$7:$A$741) -> 735 | D7: =COUNTIF('Club Colours'!$G$7:$G$741,"Both colours") -> 567 | G7: =COUNTIF('Club Colours'!$G$7:$G$741,"Primary only") -> 8 | J7: =COUNTIF('Club Colours'!$G$7:$G$741,"Needs verification") -> 160
A10: Coverage means that fields are populated, not that every palette is official or current. Read the evidence basis before using a pair in production.
A12: DISTINCT-TEAM COVERAGE BY ORIGINAL LEAGUE SYSTEM
A13: Country / system | E13: Teams | F13: Both | G13: Primary only | H13: Missing | I13: Pair coverage
A14: England | E14: =COUNTIF('Club Colours'!$B$7:$B$741,A14) -> 68 | F14: =COUNTIFS('Club Colours'!$B$7:$B$741,A14,'Club Colours'!$G$7:$G$741,"Both colours") -> 68 | G14: =COUNTIFS('Club Colours'!$B$7:$B$741,A14,'Club Colours'!$G$7:$G$741,"Primary only") -> 0 | H14: =COUNTIFS('Club Colours'!$B$7:$B$741,A14,'Club Colours'!$G$7:$G$741,"Needs verification") -> 0 | I14: =IFERROR(F14/E14,0) -> 1
A15: Spain | E15: =COUNTIF('Club Colours'!$B$7:$B$741,A15) -> 82 | F15: =COUNTIFS('Club Colours'!$B$7:$B$741,A15,'Club Colours'!$G$7:$G$741,"Both colours") -> 77 | G15: =COUNTIFS('Club Colours'!$B$7:$B$741,A15,'Club Colours'!$G$7:$G$741,"Primary only") -> 1 | H15: =COUNTIFS('Club Colours'!$B$7:$B$741,A15,'Club Colours'!$G$7:$G$741,"Needs verification") -> 4 | I15: =IFERROR(F15/E15,0) -> 0.93902439
A16: Italy | E16: =COUNTIF('Club Colours'!$B$7:$B$741,A16) -> 100 | F16: =COUNTIFS('Club Colours'!$B$7:$B$741,A16,'Club Colours'!$G$7:$G$741,"Both colours") -> 97 | G16: =COUNTIFS('Club Colours'!$B$7:$B$741,A16,'Club Colours'!$G$7:$G$741,"Primary only") -> 3 | H16: =COUNTIFS('Club Colours'!$B$7:$B$741,A16,'Club Colours'!$G$7:$G$741,"Needs verification") -> 0 | I16: =IFERROR(F16/E16,0) -> 0.97
A17: Germany | E17: =COUNTIF('Club Colours'!$B$7:$B$741,A17) -> 56 | F17: =COUNTIFS('Club Colours'!$B$7:$B$741,A17,'Club Colours'!$G$7:$G$741,"Both colours") -> 56 | G17: =COUNTIFS('Club Colours'!$B$7:$B$741,A17,'Club Colours'!$G$7:$G$741,"Primary only") -> 0 | H17: =COUNTIFS('Club Colours'!$B$7:$B$741,A17,'Club Colours'!$G$7:$G$741,"Needs verification") -> 0 | I17: =IFERROR(F17/E17,0) -> 1
A18: France | E18: =COUNTIF('Club Colours'!$B$7:$B$741,A18) -> 54 | F18: =COUNTIFS('Club Colours'!$B$7:$B$741,A18,'Club Colours'!$G$7:$G$741,"Both colours") -> 53 | G18: =COUNTIFS('Club Colours'!$B$7:$B$741,A18,'Club Colours'!$G$7:$G$741,"Primary only") -> 1 | H18: =COUNTIFS('Club Colours'!$B$7:$B$741,A18,'Club Colours'!$G$7:$G$741,"Needs verification") -> 0 | I18: =IFERROR(F18/E18,0) -> 0.98148148
A19: Romania | E19: =COUNTIF('Club Colours'!$B$7:$B$741,A19) -> 134 | F19: =COUNTIFS('Club Colours'!$B$7:$B$741,A19,'Club Colours'!$G$7:$G$741,"Both colours") -> 46 | G19: =COUNTIFS('Club Colours'!$B$7:$B$741,A19,'Club Colours'!$G$7:$G$741,"Primary only") -> 2 | H19: =COUNTIFS('Club Colours'!$B$7:$B$741,A19,'Club Colours'!$G$7:$G$741,"Needs verification") -> 86 | I19: =IFERROR(F19/E19,0) -> 0.34328358
A20: Greece | E20: =COUNTIF('Club Colours'!$B$7:$B$741,A20) -> 143 | F20: =COUNTIFS('Club Colours'!$B$7:$B$741,A20,'Club Colours'!$G$7:$G$741,"Both colours") -> 74 | G20: =COUNTIFS('Club Colours'!$B$7:$B$741,A20,'Club Colours'!$G$7:$G$741,"Primary only") -> 0 | H20: =COUNTIFS('Club Colours'!$B$7:$B$741,A20,'Club Colours'!$G$7:$G$741,"Needs verification") -> 69 | I20: =IFERROR(F20/E20,0) -> 0.51748252
A21: Finland | E21: =COUNTIF('Club Colours'!$B$7:$B$741,A21) -> 34 | F21: =COUNTIFS('Club Colours'!$B$7:$B$741,A21,'Club Colours'!$G$7:$G$741,"Both colours") -> 33 | G21: =COUNTIFS('Club Colours'!$B$7:$B$741,A21,'Club Colours'!$G$7:$G$741,"Primary only") -> 0 | H21: =COUNTIFS('Club Colours'!$B$7:$B$741,A21,'Club Colours'!$G$7:$G$741,"Needs verification") -> 1 | I21: =IFERROR(F21/E21,0) -> 0.97058824
A22: Other UEFA associations | E22: =$A$7-SUM(E14:E21) -> 64 | F22: =$D$7-SUM(F14:F21) -> 63 | G22: =$G$7-SUM(G14:G21) -> 1 | H22: =$J$7-SUM(H14:H21) -> 0 | I22: =IFERROR(F22/E22,0) -> 0.984375
A23: TOTAL | E23: =SUM(E14:E22) -> 735 | F23: =SUM(F14:F22) -> 567 | G23: =SUM(G14:G22) -> 8 | H23: =SUM(H14:H22) -> 160 | I23: =IFERROR(F23/E23,0) -> 0.77142857
A25: METHOD, SCOPE AND LIMITATIONS
A26: Identity and kit references | D26: The intended fields describe club identity colours. Where a source instead documents a traditional home-kit pair, that distinction is explicit in Evidence basis. No away-jersey colours have been substituted silently.
A28: Colour order | D28: Primary and secondary are display fields, not a certified ranking by the club. Co-primary pairs may be equally important. Known third colours and accent-only cases are recorded in Colour notes.
A30: HEX and swatches | D30: The HEX codes and cell fills are generic, illustrative shades for the colour names. They are not official club-brand values and must not be used as production branding specifications.
A32: Historical / inferred | D32: Historical references retain their source dates and require checking before current-kit use. Reserve-team colours are marked as inherited where only the parent-club palette was sourced.
A34: Unconfirmed fields | D34: A blank pair means no sufficiently clear source was established in this pass. "Not specified" means a primary colour was sourced but no defensible secondary was established. Neither means the club has no colours.
A36: Original roster retained | D36: The 779 original membership rows and 735 distinct team names are retained. This is a colour-enrichment pass, not a new audit of league membership. Any roster issue encountered is noted rather than silently changing the list.
A38: Jersey images and access | D38: Home and away jersey images are omitted, as requested. No Firecrawl or other new account connection was used. Source links are ordinary public references.
A40: Review date / freshness | D40: Research was reviewed on 11 September 2026. That date is not a claim that every historical palette remains the current kit, nor that a source has certified the generic display shades.
A44: EVIDENCE BASIS | DISTINCT TEAMS | H44: ILLUSTRATIVE DISPLAY PALETTE
A45: Club colour plus documented accent | F45: =COUNTIF('Club Colours'!$H$7:$H$741,A45) -> 3 | H45: Amaranth | K45: #A52A50
A46: Club colours reference | F46: =COUNTIF('Club Colours'!$H$7:$H$741,A46) -> 195 | H46: Amber | K46: #FFBF00
A47: Colour nickname reference | F47: =COUNTIF('Club Colours'!$H$7:$H$741,A47) -> 35 | H47: Black | K47: #111111
A48: Historical club-colours reference | F48: =COUNTIF('Club Colours'!$H$7:$H$741,A48) -> 72 | H48: Blue | K48: #1565C0
A49: Historical kit reference | F49: =COUNTIF('Club Colours'!$H$7:$H$741,A49) -> 225 | H49: Brown | K49: #795548
A50: Official club reference | F50: =COUNTIF('Club Colours'!$H$7:$H$741,A50) -> 6 | H50: Burgundy | K50: #800020
A51: Official home-kit reference | F51: =COUNTIF('Club Colours'!$H$7:$H$741,A51) -> 1 | H51: Cherry red | K51: #B5123B
A52: Official league reference | F52: =COUNTIF('Club Colours'!$H$7:$H$741,A52) -> 1 | H52: Claret | K52: #7F1734
A53: Parent-club palette (inferred) | F53: =COUNTIF('Club Colours'!$H$7:$H$741,A53) -> 26 | H53: Crimson | K53: #DC143C
A54: Third-party palette reference | F54: =COUNTIF('Club Colours'!$H$7:$H$741,A54) -> 6 | H54: Garnet | K54: #733635
A55: Traditional kit reference | F55: =COUNTIF('Club Colours'!$H$7:$H$741,A55) -> 5 | H55: Gold | K55: #D4AF37
A56: Unresolved | F56: =COUNTIF('Club Colours'!$H$7:$H$741,A56) -> 160 | H56: Green | K56: #15803D
...

Sheet All Teams
A1: ALL TEAMS | TEAM DIRECTORY | L1: CLUB COLOURS | REFERENCE DATA
A3: 2026/27 except Finland 2026 | Domestic + UEFA memberships | League phase only for UEFA | Checked 11 Sep 2026 | L3: Generic display shades, not official brand HEX values. Historical and inferred palettes are labelled.
A4: Return to Overview | Filters are in row 6. Sources and scope notes are included in this workbook. | L4: Open Club Colours for a compact colour-only directory and approximate HEX codes.
A6: Team | B6: Country / system | C6: Competition | D6: Tier | E6: Group / phase | F6: Season | G6: Scope | H6: Team type | I6: Notes | J6: Source ID | K6: Source URL | L6: Primary colour | M6: Secondary colour | N6: Colour coverage | O6: Colour evidence basis | P6: Colour source URL | Q6: Colour notes
A7: Arsenal | B7: England | C7: Premier League | D7: 1 | E7: Single division | F7: 2026/27 | G7: Domestic | H7: First team | J7: S01 | K7: https://www.premierleague.com/en/clubs | L7: Red | M7: White | N7: Both colours | O7: Historical kit reference | P7: https://www.rsssf.org/colours/england.html | Q7: Historical reference dated 2006. Traditional home-kit reference; not a 2026/27 kit check.
A8: Aston Villa | B8: England | C8: Premier League | D8: 1 | E8: Single division | F8: 2026/27 | G8: Domestic | H8: First team | J8: S01 | K8: https://www.premierleague.com/en/clubs | L8: Claret | M8: Sky blue | N8: Both colours | O8: Historical kit reference | P8: https://www.rsssf.org/colours/england.html | Q8: Historical reference dated 2006. Traditional home-kit reference; not a 2026/27 kit check.
A9: Bournemouth | B9: England | C9: Premier League | D9: 1 | E9: Single division | F9: 2026/27 | G9: Domestic | H9: First team | J9: S01 | K9: https://www.premierleague.com/en/clubs | L9: Red | M9: Black | N9: Both colours | O9: Club colours reference | P9: https://en.wikipedia.org/wiki/AFC_Bournemouth
A10: Brentford | B10: England | C10: Premier League | D10: 1 | E10: Single division | F10: 2026/27 | G10: Domestic | H10: First team | J10: S01 | K10: https://www.premierleague.com/en/clubs | L10: Red | M10: White | N10: Both colours | O10: Club colours reference | P10: https://en.wikipedia.org/wiki/Brentford_F.C. | Q10: Black is an additional traditional kit colour.
A11: Brighton and Hove Albion | B11: England | C11: Premier League | D11: 1 | E11: Single division | F11: 2026/27 | G11: Domestic | H11: First team | J11: S01 | K11: https://www.premierleague.com/en/clubs | L11: Blue | M11: White | N11: Both colours | O11: Historical kit reference | P11: https://www.rsssf.org/colours/england.html | Q11: Historical reference dated 2006. Traditional home-kit reference; not a 2026/27 kit check.
A12: Chelsea | B12: England | C12: Premier League | D12: 1 | E12: Single division | F12: 2026/27 | G12: Domestic | H12: First team | J12: S01 | K12: https://www.premierleague.com/en/clubs | L12: Blue | M12: White | N12: Both colours | O12: Historical kit reference | P12: https://www.rsssf.org/colours/england.html | Q12: Historical reference dated 2006. Traditional home-kit reference; not a 2026/27 kit check.
A13: Coventry City | B13: England | C13: Premier League | D13: 1 | E13: Single division | F13: 2026/27 | G13: Domestic | H13: First team | J13: S01 | K13: https://www.premierleague.com/en/clubs | L13: Sky blue | M13: White | N13: Both colours | O13: Club colours reference | P13: https://en.wikipedia.org/wiki/Coventry_City_F.C. | Q13: White is a traditional accent; sky blue is the defining colour.
A14: Crystal Palace | B14: England | C14: Premier League | D14: 1 | E14: Single division | F14: 2026/27 | G14: Domestic | H14: First team | J14: S01 | K14: https://www.premierleague.com/en/clubs | L14: Red | M14: Blue | N14: Both colours | O14: Historical kit reference | P14: https://www.rsssf.org/colours/england.html | Q14: Historical reference dated 2006. Traditional home-kit reference; not a 2026/27 kit check.
A15: Everton | B15: England | C15: Premier League | D15: 1 | E15: Single division | F15: 2026/27 | G15: Domestic | H15: First team | J15: S01 | K15: https://www.premierleague.com/en/clubs | L15: Blue | M15: White | N15: Both colours | O15: Historical kit reference | P15: https://www.rsssf.org/colours/england.html | Q15: Historical reference dated 2006. Traditional home-kit reference; not a 2026/27 kit check.
A16: Fulham | B16: England | C16: Premier League | D16: 1 | E16: Single division | F16: 2026/27 | G16: Domestic | H16: First team | J16: S01 | K16: https://www.premierleague.com/en/clubs | L16: White | M16: Black | N16: Both colours | O16: Historical kit reference | P16: https://www.rsssf.org/colours/england.html | Q16: Historical reference dated 2006. Traditional home-kit reference; not a 2026/27 kit check.
A17: Hull City | B17: England | C17: Premier League | D17: 1 | E17: Single division | F17: 2026/27 | G17: Domestic | H17: First team | J17: S01 | K17: https://www.premierleague.com/en/clubs | L17: Amber | M17: Black | N17: Both colours | O17: Historical kit reference | P17: https://www.rsssf.org/colours/england.html | Q17: Historical reference dated 2006. Traditional home-kit reference; not a 2026/27 kit check.
A18: Ipswich Town | B18: England | C18: Premier League | D18: 1 | E18: Single division | F18: 2026/27 | G18: Domestic | H18: First team | J18: S01 | K18: https://www.premierleague.com/en/clubs | L18: Blue | M18: White | N18: Both colours | O18: Historical kit reference | P18: https://www.rsssf.org/colours/england.html | Q18: Historical reference dated 2006. Traditional home-kit reference; not a 2026/27 kit check.
A19: Leeds United | B19: England | C19: Premier League | D19: 1 | E19: Single division | F19: 2026/27 | G19: Domestic | H19: First team | J19: S01 | K19: https://www.premierleague.com/en/clubs | L19: White | M19: Blue | N19: Both colours | O19: Historical kit reference | P19: https://www.rsssf.org/colours/england.html | Q19: Historical reference dated 2006. Traditional home-kit reference; not a 2026/27 kit check. Yellow is an additional colour.
A20: Liverpool | B20: England | C20: Premier League | D20: 1 | E20: Single division | F20: 2026/27 | G20: Domestic | H20: First team | J20: S01 | K20: https://www.premierleague.com/en/clubs | L20: Red | M20: White | N20: Both colours | O20: Club colours reference | P20: https://en.wikipedia.org/wiki/Liverpool_F.C. | Q20: White is a historical secondary/accent colour; the usual home strip is all red.
A21: Manchester City | B21: England | C21: Premier League | D21: 1 | E21: Single division | F21: 2026/27 | G21: Domestic | H21: First team | J21: S01 | K21: https://www.premierleague.com/en/clubs | L21: Sky blue | M21: White | N21: Both colours | O21: Historical kit reference | P21: https://www.rsssf.org/colours/england.html | Q21: Historical reference dated 2006. Traditional home-kit reference; not a 2026/27 kit check.
... A31: Burnley | B31: England | C31: EFL Championship | D31: 2 | E31: Single division | F31: 2026/27 | G31: Domestic | H31: First team | J31: S02 | K31: https://www.efl.com/news/2026/august/22/sky-bet-championship-results--table---stats/ | L31: Claret | M31: Sky blue | N31: Both colours | O31: Historical kit reference | P31: https://www.rsssf.org/colours/england.html | Q31: Historical reference dated 2006. Traditional home-kit reference; not a 2026/27 kit check.
A32: Cardiff City | B32: England | C32: EFL Championship | D32: 2 | E32: Single division | F32: 2026/27 | G32: Domestic | H32: First team | I32: Welsh club in the English league system. | J32: S02 | K32: https://www.efl.com/news/2026/august/22/sky-bet-championship-results--table---stats/ | L32: Blue | M32: White | N32: Both colours | O32: Historical kit reference | P32: https://www.rsssf.org/colours/england.html | Q32: Historical reference dated 2006. Traditional home-kit reference; not a 2026/27 kit check.
A33: Charlton Athletic | B33: England | C33: EFL Championship | D33: 2 | E33: Single division | F33: 2026/27 | G33: Domestic | H33: First team | J33: S02 | K33: https://www.efl.com/news/2026/august/22/sky-bet-championship-results--table---stats/ | L33: Red | M33: White | N33: Both colours | O33: Historical kit reference | P33: https://www.rsssf.org/colours/england.html | Q33: Historical reference dated 2006. Traditional home-kit reference; not a 2026/27 kit check.
A34: Derby County | B34: England | C34: EFL Championship | D34: 2 | E34: Single division | F34: 2026/27 | G34: Domestic | H34: First team | J34: S02 | K34: https://www.efl.com/news/2026/august/22/sky-bet-championship-results--table---stats/ | L34: White | M34: Black | N34: Both colours | O34: Historical kit reference | P34: https://www.rsssf.org/colours/england.html | Q34: Historical reference dated 2006. Traditional home-kit reference; not a 2026/27 kit check.
A35: Lincoln City | B35: England | C35: EFL Championship | D35: 2 | E35: Single division | F35: 2026/27 | G35: Domestic | H35: First team | J35: S02 | K35: https://www.efl.com/news/2026/august/22/sky-bet-championship-results--table---stats/ | L35: Red | M35: White | N35: Both colours | O35: Historical kit reference | P35: https://www.rsssf.org/colours/england.html | Q35: Historical reference dated 2006. Traditional home-kit reference; not a 2026/27 kit check.
A36: Middlesbrough | B36: England | C36: EFL Championship | D36: 2 | E36: Single division | F36: 2026/27 | G36: Domestic | H36: First team | J36: S02 | K36: https://www.efl.com/news/2026/august/22/sky-bet-championship-results--table---stats/ | L36: Red | M36: White | N36: Both colours | O36: Historical kit reference | P36: https://www.rsssf.org/colours/england.html | Q36: Historical reference dated 2006. Traditional home-kit reference; not a 2026/27 kit check.
A37: Millwall | B37: England | C37: EFL Championship | D37: 2 | E37: Single division | F37: 2026/27 | G37: Domestic | H37: First team | J37: S02 | K37: https://www.efl.com/news/2026/august/22/sky-bet-championship-results--table---stats/ | L37: Blue | M37: White | N37: Both colours | O37: Historical kit reference | P37: https://www.rsssf.org/colours/england.html | Q37: Historical reference dated 2006. Traditional home-kit reference; not a 2026/27 kit check.
A38: Norwich City | B38: England | C38: EFL Championship | D38: 2 | E38: Single division | F38: 2026/27 | G38: Domestic | H38: First team | J38: S02 | K38: https://www.efl.com/news/2026/august/22/sky-bet-championship-results--table---stats/ | L38: Yellow | M38: Green | N38: Both colours | O38: Historical kit reference | P38: https://www.rsssf.org/colours/england.html | Q38: Historical reference dated 2006. Traditional home-kit reference; not a 2026/27 kit check.
A39: Portsmouth | B39: England | C39: EFL Championship | D39: 2 | E39: Single division | F39: 2026/27 | G39: Domestic | H39: First team | J39: S02 | K39: https://www.efl.com/news/2026/august/22/sky-bet-championship-results--table---stats/ | L39: Blue | M39: White | N39: Both colours | O39: Historical kit reference | P39: https://www.rsssf.org/colours/england.html | Q39: Historical reference dated 2006. Traditional home-kit reference; not a 2026/27 kit check. Red is an additional colour.
A40: Preston North End | B40: England | C40: EFL Championship | D40: 2 | E40: Single division | F40: 2026/27 | G40: Domestic | H40: First team | J40: S02 | K40: https://www.efl.com/news/2026/august/22/sky-bet-championship-results--table---stats/ | L40: White | M40: Navy blue | N40: Both colours | O40: Historical kit reference | P40: https://www.rsssf.org/colours/england.html | Q40: Historical reference dated 2006. Traditional home-kit reference; not a 2026/27 kit check.
A41: Queens Park Rangers | B41: England | C41: EFL Championship | D41: 2 | E41: Single division | F41: 2026/27 | G41: Domestic | H41: First team | J41: S02 | K41: https://www.efl.com/news/2026/august/22/sky-bet-championship-results--table---stats/ | L41: Blue | M41: White | N41: Both colours | O41: Historical kit reference | P41: https://www.rsssf.org/colours/england.html | Q41: Historical reference dated 2006. Traditional home-kit reference; not a 2026/27 kit check.
A42: Sheffield United | B42: England | C42: EFL Championship | D42: 2 | E42: Single division | F42: 2026/27 | G42: Domestic | H42: First team | J42: S02 | K42: https://www.efl.com/news/2026/august/22/sky-bet-championship-results--table---stats/ | L42: Red | M42: White | N42: Both colours | O42: Historical kit reference | P42: https://www.rsssf.org/colours/england.html | Q42: Historical reference dated 2006. Traditional home-kit reference; not a 2026/27 kit check. Black is an additional colour.
A43: Southampton | B43: England | C43: EFL Championship | D43: 2 | E43: Single division | F43: 2026/27 | G43: Domestic | H43: First team | J43: S02 | K43: https://www.efl.com/news/2026/august/22/sky-bet-championship-results--table---stats/ | L43: Red | M43: White | N43: Both colours | O43: Historical kit reference | P43: https://www.rsssf.org/colours/england.html | Q43: Historical reference dated 2006. Traditional home-kit reference; not a 2026/27 kit check.
A44: Stoke City | B44: England | C44: EFL Championship | D44: 2 | E44: Single division | F44: 2026/27 | G44: Domestic | H44: First team | J44: S02 | K44: https://www.efl.com/news/2026/august/22/sky-bet-championship-results--table---stats/ | L44: Red | M44: White | N44: Both colours | O44: Historical kit reference | P44: https://www.rsssf.org/colours/england.html | Q44: Historical reference dated 2006. Traditional home-kit reference; not a 2026/27 kit check.
A45: Swansea City | B45: England | C45: EFL Championship | D45: 2 | E45: Single division | F45: 2026/27 | G45: Domestic | H45: First team | I45: Welsh club in the English league system. | J45: S02 | K45: https://www.efl.com/news/2026/august/22/sky-bet-championship-results--table---stats/ | L45: White | M45: Black | N45: Both colours | O45: Historical kit reference | P45: https://www.rsssf.org/colours/england.html | Q45: Historical reference dated 2006. Traditional home-kit reference; not a 2026/27 kit check.
A46: Watford | B46: England | C46: EFL Championship | D46: 2 | E46: Single division | F46: 2026/27 | G46: Domestic | H46: First team | J46: S02 | K46: https://www.efl.com/news/2026/august/22/sky-bet-championship-results--table---stats/ | L46: Yellow | M46: Black | N46: Both colours | O46: Traditional kit reference | P46: https://www.football-stadiums.co.uk/articles/football-club-kit-colours/
A47: West Bromwich Albion | B47: England | C47: EFL Championship | D47: 2 | E47: Single division | F47: 2026/27 | G47: Domestic | H47: First team | J47: S02 | K47: https://www.efl.com/news/2026/august/22/sky-bet-championship-results--table---stats/ | L47: Navy blue | M47: White | N47: Both colours | O47: Club colours reference | P47: https://en.wikipedia.org/wiki/West_Bromwich_Albion_F.C.
A48: West Ham United | B48: England | C48: EFL Championship | D48: 2 | E48: Single division | F48: 2026/27 | G48: Domestic | H48: First team | J48: S02 | K48: https://www.efl.com/news/2026/august/22/sky-bet-championship-results--table---stats/ | L48: Claret | M48: Sky blue | N48: Both colours | O48: Historical kit reference | P48: https://www.rsssf.org/colours/england.html | Q48: Historical reference dated 2006. Traditional home-kit reference; not a 2026/27 kit check.
A49: Wolverhampton Wanderers | B49: England | C49: EFL Championship | D49: 2 | E49: Single division | F49: 2026/27 | G49: Domestic | H49: First team | J49: S02 | K49: https://www.efl.com/news/2026/august/22/sky-bet-championship-results--table---stats/ | L49: Old gold | M49: Black | N49: Both colours | O49: Historical kit reference | P49: https://www.rsssf.org/colours/england.html | Q49: Historical reference dated 2006. Traditional home-kit reference; not a 2026/27 kit check.
A50: Wrexham | B50: England | C50: EFL Championship | D50: 2 | E50: Single division | F50: 2026/27 | G50: Domestic | H50: First team | I50: Welsh club in the English league system. | J50: S02 | K50: https://www.efl.com/news/2026/august/22/sky-bet-championship-results--table---stats/ | L50: Red | M50: White | N50: Both colours | O50: Club colours reference | P50: https://en.wikipedia.org/wiki/Wrexham_A.F.C.
A51: AFC Wimbledon | B51: England | C51: EFL League One | D51: 3 | E51: Single division | F51: 2026/27 | G51: Domestic | H51: First team | J51: S03 | K51: https://www.efl.com/competitions/efl-league-one/ | L51: Royal blue | M51: Yellow | N51: Both colours | O51: Club colours reference | P51: https://en.wikipedia.org/wiki/AFC_Wimbledon
...

Sheet Competitions
A1: COMPETITIONS | COVERAGE CHECK
A3: 27 competitions | Expected membership compared with rows in All Teams | Group counts include all regional divisions
A4: Return to Overview | Filters are in row 6. Sources and scope notes are included in this workbook.
A6: Country / system | B6: Competition | C6: Tier | D6: Season | E6: Groups | F6: Expected teams | G6: Listed teams | H6: Check | I6: Scope | J6: Notes | K6: Source ID | L6: Source URL
A7: England | B7: Premier League | C7: 1 | D7: 2026/27 | E7: 1 | F7: 20 | G7: =COUNTIF('All Teams'!$C$7:$C$785,B7) -> 20 | H7: =IF(F7=G7,"OK","REVIEW") -> OK | I7: Domestic | K7: S01 | L7: https://www.premierleague.com/en/clubs
A8: England | B8: EFL Championship | C8: 2 | D8: 2026/27 | E8: 1 | F8: 24 | G8: =COUNTIF('All Teams'!$C$7:$C$785,B8) -> 24 | H8: =IF(F8=G8,"OK","REVIEW") -> OK | I8: Domestic | K8: S02 | L8: https://www.efl.com/news/2026/august/22/sky-bet-championship-results--table---stats/
A9: England | B9: EFL League One | C9: 3 | D9: 2026/27 | E9: 1 | F9: 24 | G9: =COUNTIF('All Teams'!$C$7:$C$785,B9) -> 24 | H9: =IF(F9=G9,"OK","REVIEW") -> OK | I9: Domestic | K9: S03 | L9: https://www.efl.com/competitions/efl-league-one/
A10: Spain | B10: LaLiga | C10: 1 | D10: 2026/27 | E10: 1 | F10: 20 | G10: =COUNTIF('All Teams'!$C$7:$C$785,B10) -> 20 | H10: =IF(F10=G10,"OK","REVIEW") -> OK | I10: Domestic | K10: S04 | L10: https://www.laliga.com/en-GB/laliga-easports/clubs
A11: Spain | B11: Segunda División | C11: 2 | D11: 2026/27 | E11: 1 | F11: 22 | G11: =COUNTIF('All Teams'!$C$7:$C$785,B11) -> 22 | H11: =IF(F11=G11,"OK","REVIEW") -> OK | I11: Domestic | K11: S05 | L11: https://www.laliga.com/en-GB/laliga-hypermotion/clubs
A12: Spain | B12: Primera Federación | C12: 3 | D12: 2026/27 | E12: 2 | F12: 40 | G12: =COUNTIF('All Teams'!$C$7:$C$785,B12) -> 40 | H12: =IF(F12=G12,"OK","REVIEW") -> OK | I12: Domestic | J12: Both regional groups included. This is the third tier, not Segunda Federacion. | K12: S06 | L12: https://rfef.es/es/noticias/aprobados-los-grupos-de-primera-federacion-para-la-temporada-202627
A13: Italy | B13: Serie A | C13: 1 | D13: 2026/27 | E13: 1 | F13: 20 | G13: =COUNTIF('All Teams'!$C$7:$C$785,B13) -> 20 | H13: =IF(F13=G13,"OK","REVIEW") -> OK | I13: Domestic | K13: S07 | L13: https://sport.virgilio.it/calcio/squadre/
A14: Italy | B14: Serie B | C14: 2 | D14: 2026/27 | E14: 1 | F14: 20 | G14: =COUNTIF('All Teams'!$C$7:$C$785,B14) -> 20 | H14: =IF(F14=G14,"OK","REVIEW") -> OK | I14: Domestic | K14: S07 | L14: https://sport.virgilio.it/calcio/squadre/
A15: Italy | B15: Serie C | C15: 3 | D15: 2026/27 | E15: 3 | F15: 60 | G15: =COUNTIF('All Teams'!$C$7:$C$785,B15) -> 60 | H15: =IF(F15=G15,"OK","REVIEW") -> OK | I15: Domestic | J15: All three regional groups included. | K15: S08 | L15: https://it.blastingnews.com/calcio/2026/07/ultimora-serie-c-svelati-i-gironi-ufficiali-2026-27-004083523.html
A16: Germany | B16: Bundesliga | C16: 1 | D16: 2026/27 | E16: 1 | F16: 18 | G16: =COUNTIF('All Teams'!$C$7:$C$785,B16) -> 18 | H16: =IF(F16=G16,"OK","REVIEW") -> OK | I16: Domestic | K16: S09 | L16: https://en.wikipedia.org/wiki/2026%E2%80%9327_Bundesliga
A17: Germany | B17: 2. Bundesliga | C17: 2 | D17: 2026/27 | E17: 1 | F17: 18 | G17: =COUNTIF('All Teams'!$C$7:$C$785,B17) -> 18 | H17: =IF(F17=G17,"OK","REVIEW") -> OK | I17: Domestic | K17: S10 | L17: https://www.bundesliga.com/de/2bundesliga/tabelle?view=full
A18: Germany | B18: 3. Liga | C18: 3 | D18: 2026/27 | E18: 1 | F18: 20 | G18: =COUNTIF('All Teams'!$C$7:$C$785,B18) -> 20 | H18: =IF(F18=G18,"OK","REVIEW") -> OK | I18: Domestic | J18: Licensed field; TSV Havelse replaces TSV 1860 Munich. | K18: S11 | L18: https://www.dfb.de/news/teilnehmerfeld-der-3-liga-steht-fest-havelse-rueckt-fuer-1860-nach
A19: France | B19: Ligue 1 | C19: 1 | D19: 2026/27 | E19: 1 | F19: 18 | G19: =COUNTIF('All Teams'!$C$7:$C$785,B19) -> 18 | H19: =IF(F19=G19,"OK","REVIEW") -> OK | I19: Domestic | K19: S12 | L19: https://ligue1.com/en/articles/l1_article_5292-the-2026-27-ligue-1-mc-donald-s-calendar-is-released
A20: France | B20: Ligue 2 | C20: 2 | D20: 2026/27 | E20: 1 | F20: 18 | G20: =COUNTIF('All Teams'!$C$7:$C$785,B20) -> 18 | H20: =IF(F20=G20,"OK","REVIEW") -> OK | I20: Domestic | K20: S13 | L20: https://en.wikipedia.org/wiki/2026%E2%80%9327_Ligue_2
A21: France | B21: Ligue 3 | C21: 3 | D21: 2026/27 | E21: 1 | F21: 18 | G21: =COUNTIF('All Teams'!$C$7:$C$785,B21) -> 18 | H21: =IF(F21=G21,"OK","REVIEW") -> OK | I21: Domestic | J21: Formerly Championnat National; renamed Ligue 3 for 2026/27. | K21: S14 | L21: https://www.fff.fr/article/17022-le-calendrier-2026-2027-est-servi.html
A22: Romania | B22: SuperLiga | C22: 1 | D22: 2026/27 | E22: 1 | F22: 16 | G22: =COUNTIF('All Teams'!$C$7:$C$785,B22) -> 16 | H22: =IF(F22=G22,"OK","REVIEW") -> OK | I22: Domestic | K22: S16 | L22: https://lpf.ro/liga-1
A23: Romania | B23: Liga II | C23: 2 | D23: 2026/27 | E23: 1 | F23: 22 | G23: =COUNTIF('All Teams'!$C$7:$C$785,B23) -> 22 | H23: =IF(F23=G23,"OK","REVIEW") -> OK | I23: Domestic | K23: S17 | L23: https://www.frf.ro/competitii/competitii-masculin/liga-2-casa-pariurilor/au-fost-stabilite-meciurile-sezonului-regular-2026-2027-din-liga-2-casa-pariurilor/
A24: Romania | B24: Liga III | C24: 3 | D24: 2026/27 | E24: 8 | F24: 96 | G24: =COUNTIF('All Teams'!$C$7:$C$785,B24) -> 96 | H24: =IF(F24=G24,"OK","REVIEW") -> OK | I24: Domestic | J24: All eight regional series included; 12 entrants per series. | K24: S20 | L24: https://www.frf.ro/recomandate/s-a-tras-la-sorti-programul-seriilor-din-superscore-liga-3-editia-2026-2027/
A25: Greece | B25: Super League | C25: 1 | D25: 2026/27 | E25: 1 | F25: 14 | G25: =COUNTIF('All Teams'!$C$7:$C$785,B25) -> 14 | H25: =IF(F25=G25,"OK","REVIEW") -> OK | I25: Domestic | K25: S21 | L25: https://www.slgr.gr/en/teams/
A26: Greece | B26: Super League 2 | C26: 2 | D26: 2026/27 | E26: 1 | F26: 16 | G26: =COUNTIF('All Teams'!$C$7:$C$785,B26) -> 16 | H26: =IF(F26=G26,"OK","REVIEW") -> OK | I26: Domestic | J26: Unified division in 2026/27; not the previous two-group format. | K26: S22 | L26: https://en.wikipedia.org/wiki/2026%E2%80%9327_Super_League_Greece_2
A27: Greece | B27: Gamma Ethniki | C27: 3 | D27: 2026/27 | E27: 10 | F27: 113 | G27: =COUNTIF('All Teams'!$C$7:$C$785,B27) -> 113 | H27: =IF(F27=G27,"OK","REVIEW") -> OK | I27: Domestic | J27: Published pre-season entrants: all ten groups; opening matches are scheduled after the snapshot date. | K27: S23 | L27: https://en.wikipedia.org/wiki/2026%E2%80%9327_Gamma_Ethniki
A28: Finland | B28: Veikkausliiga | C28: 1 | D28: 2026 | E28: 1 | F28: 12 | G28: =COUNTIF('All Teams'!$C$7:$C$785,B28) -> 12 | H28: =IF(F28=G28,"OK","REVIEW") -> OK | I28: Domestic | K28: S28 | L28: https://www.veikkausliiga.com/tilastot/joukkueet/
A29: Finland | B29: Ykkösliiga | C29: 2 | D29: 2026 | E29: 1 | F29: 10 | G29: =COUNTIF('All Teams'!$C$7:$C$785,B29) -> 10 | H29: =IF(F29=G29,"OK","REVIEW") -> OK | I29: Domestic | K29: S29 | L29: https://www.transfermarkt.co.uk/ykkonen/startseite/wettbewerb/FI2
A30: Finland | B30: Ykkönen | C30: 3 | D30: 2026 | E30: 1 | F30: 12 | G30: =COUNTIF('All Teams'!$C$7:$C$785,B30) -> 12 | H30: =IF(F30=G30,"OK","REVIEW") -> OK | I30: Domestic | J30: Ykkonen is the third tier; all regular-season participants included once. | K30: S30 | L30: https://www.palloliitto.fi/ajankohtaista/ykkosen-jatkosarjojen-ohjelma-kaudelle-2026-julkaistu
A31: UEFA | B31: UEFA Champions League | C31: - | D31: 2026/27 | E31: 1 | F31: 36 | G31: =COUNTIF('All Teams'!$C$7:$C$785,B31) -> 36 | H31: =IF(F31=G31,"OK","REVIEW") -> OK | I31: UEFA | J31: League phase only; qualifying-only entrants excluded. | K31: S32 | L31: https://www.uefa.com/uefachampionsleague/news/02a6-20d57cfcd03e-407c22a7f465-1000--2026-27-champions-league-teams-dates-draws-format-final/
A32: UEFA | B32: UEFA Europa League | C32: - | D32: 2026/27 | E32: 1 | F32: 36 | G32: =COUNTIF('All Teams'!$C$7:$C$785,B32) -> 36 | H32: =IF(F32=G32,"OK","REVIEW") -> OK | I32: UEFA | J32: League phase only; qualifying-only entrants excluded. | K32: S33 | L32: https://www.uefa.com/uefaeuropaleague/clubs/
A33: UEFA | B33: UEFA Conference League | C33: - | D33: 2026/27 | E33: 1 | F33: 36 | G33: =COUNTIF('All Teams'!$C$7:$C$785,B33) -> 36 | H33: =IF(F33=G33,"OK","REVIEW") -> OK | I33: UEFA | J33: League phase only; qualifying-only entrants excluded. | K33: S34 | L33: https://www.uefa.com/uefaconferenceleague/news/02a8-21737138dae7-37bfb18d9aa7-1000--2026-27-conference-league-who-has-qualified-for-the-league-/

Sheet England
A1: ENGLAND | TEAM DIRECTORY | L1: CLUB COLOURS | REFERENCE DATA
A3: Men's domestic football | Season 2026/27 | Top three tiers, all regional groups | Checked 11 Sep 2026 | L3: Generic display shades, not official brand HEX values. Historical and inferred palettes are labelled.
A4: Return to Overview | Filters are in row 6. Sources and scope notes are included in this workbook. | L4: Open Club Colours for a compact colour-only directory and approximate HEX codes.
A6: Team | B6: Country / system | C6: Competition | D6: Tier | E6: Group / phase | F6: Season | G6: Scope | H6: Team type | I6: Notes | J6: Source ID | K6: Source URL | L6: Primary colour | M6: Secondary colour | N6: Colour coverage | O6: Colour evidence basis | P6: Colour source URL | Q6: Colour notes
A7: Arsenal | B7: England | C7: Premier League | D7: 1 | E7: Single division | F7: 2026/27 | G7: Domestic | H7: First team | J7: S01 | K7: https://www.premierleague.com/en/clubs | L7: Red | M7: White | N7: Both colours | O7: Historical kit reference | P7: https://www.rsssf.org/colours/england.html | Q7: Historical reference dated 2006. Traditional home-kit reference; not a 2026/27 kit check.
A8: Aston Villa | B8: England | C8: Premier League | D8: 1 | E8: Single division | F8: 2026/27 | G8: Domestic | H8: First team | J8: S01 | K8: https://www.premierleague.com/en/clubs | L8: Claret | M8: Sky blue | N8: Both colours | O8: Historical kit reference | P8: https://www.rsssf.org/colours/england.html | Q8: Historical reference dated 2006. Traditional home-kit reference; not a 2026/27 kit check.
A9: Bournemouth | B9: England | C9: Premier League | D9: 1 | E9: Single division | F9: 2026/27 | G9: Domestic | H9: First team | J9: S01 | K9: https://www.premierleague.com/en/clubs | L9: Red | M9: Black | N9: Both colours | O9: Club colours reference | P9: https://en.wikipedia.org/wiki/AFC_Bournemouth
A10: Brentford | B10: England | C10: Premier League | D10: 1 | E10: Single division | F10: 2026/27 | G10: Domestic | H10: First team | J10: S01 | K10: https://www.premierleague.com/en/clubs | L10: Red | M10: White | N10: Both colours | O10: Club colours reference | P10: https://en.wikipedia.org/wiki/Brentford_F.C. | Q10: Black is an additional traditional kit colour.
A11: Brighton and Hove Albion | B11: England | C11: Premier League | D11: 1 | E11: Single division | F11: 2026/27 | G11: Domestic | H11: First team | J11: S01 | K11: https://www.premierleague.com/en/clubs | L11: Blue | M11: White | N11: Both colours | O11: Historical kit reference | P11: https://www.rsssf.org/colours/england.html | Q11: Historical reference dated 2006. Traditional home-kit reference; not a 2026/27 kit check.
A12: Chelsea | B12: England | C12: Premier League | D12: 1 | E12: Single division | F12: 2026/27 | G12: Domestic | H12: First team | J12: S01 | K12: https://www.premierleague.com/en/clubs | L12: Blue | M12: White | N12: Both colours | O12: Historical kit reference | P12: https://www.rsssf.org/colours/england.html | Q12: Historical reference dated 2006. Traditional home-kit reference; not a 2026/27 kit check.
A13: Coventry City | B13: England | C13: Premier League | D13: 1 | E13: Single division | F13: 2026/27 | G13: Domestic | H13: First team | J13: S01 | K13: https://www.premierleague.com/en/clubs | L13: Sky blue | M13: White | N13: Both colours | O13: Club colours reference | P13: https://en.wikipedia.org/wiki/Coventry_City_F.C. | Q13: White is a traditional accent; sky blue is the defining colour.
A14: Crystal Palace | B14: England | C14: Premier League | D14: 1 | E14: Single division | F14: 2026/27 | G14: Domestic | H14: First team | J14: S01 | K14: https://www.premierleague.com/en/clubs | L14: Red | M14: Blue | N14: Both colours | O14: Historical kit reference | P14: https://www.rsssf.org/colours/england.html | Q14: Historical reference dated 2006. Traditional home-kit reference; not a 2026/27 kit check.
A15: Everton | B15: England | C15: Premier League | D15: 1 | E15: Single division | F15: 2026/27 | G15: Domestic | H15: First team | J15: S01 | K15: https://www.premierleague.com/en/clubs | L15: Blue | M15: White | N15: Both colours | O15: Historical kit reference | P15: https://www.rsssf.org/colours/england.html | Q15: Historical reference dated 2006. Traditional home-kit reference; not a 2026/27 kit check.
A16: Fulham | B16: England | C16: Premier League | D16: 1 | E16: Single division | F16: 2026/27 | G16: Domestic | H16: First team | J16: S01 | K16: https://www.premierleague.com/en/clubs | L16: White | M16: Black | N16: Both colours | O16: Historical kit reference | P16: https://www.rsssf.org/colours/england.html | Q16: Historical reference dated 2006. Traditional home-kit reference; not a 2026/27 kit check.
A17: Hull City | B17: England | C17: Premier League | D17: 1 | E17: Single division | F17: 2026/27 | G17: Domestic | H17: First team | J17: S01 | K17: https://www.premierleague.com/en/clubs | L17: Amber | M17: Black | N17: Both colours | O17: Historical kit reference | P17: https://www.rsssf.org/colours/england.html | Q17: Historical reference dated 2006. Traditional home-kit reference; not a 2026/27 kit check.
A18: Ipswich Town | B18: England | C18: Premier League | D18: 1 | E18: Single division | F18: 2026/27 | G18: Domestic | H18: First team | J18: S01 | K18: https://www.premierleague.com/en/clubs | L18: Blue | M18: White | N18: Both colours | O18: Historical kit reference | P18: https://www.rsssf.org/colours/england.html | Q18: Historical reference dated 2006. Traditional home-kit reference; not a 2026/27 kit check.
A19: Leeds United | B19: England | C19: Premier League | D19: 1 | E19: Single division | F19: 2026/27 | G19: Domestic | H19: First team | J19: S01 | K19: https://www.premierleague.com/en/clubs | L19: White | M19: Blue | N19: Both colours | O19: Historical kit reference | P19: https://www.rsssf.org/colours/england.html | Q19: Historical reference dated 2006. Traditional home-kit reference; not a 2026/27 kit check. Yellow is an additional colour.
A20: Liverpool | B20: England | C20: Premier League | D20: 1 | E20: Single division | F20: 2026/27 | G20: Domestic | H20: First team | J20: S01 | K20: https://www.premierleague.com/en/clubs | L20: Red | M20: White | N20: Both colours | O20: Club colours reference | P20: https://en.wikipedia.org/wiki/Liverpool_F.C. | Q20: White is a historical secondary/accent colour; the usual home strip is all red.
A21: Manchester City | B21: England | C21: Premier League | D21: 1 | E21: Single division | F21: 2026/27 | G21: Domestic | H21: First team | J21: S01 | K21: https://www.premierleague.com/en/clubs | L21: Sky blue | M21: White | N21: Both colours | O21: Historical kit reference | P21: https://www.rsssf.org/colours/england.html | Q21: Historical reference dated 2006. Traditional home-kit reference; not a 2026/27 kit check.
... A31: Burnley | B31: England | C31: EFL Championship | D31: 2 | E31: Single division | F31: 2026/27 | G31: Domestic | H31: First team | J31: S02 | K31: https://www.efl.com/news/2026/august/22/sky-bet-championship-results--table---stats/ | L31: Claret | M31: Sky blue | N31: Both colours | O31: Historical kit reference | P31: https://www.rsssf.org/colours/england.html | Q31: Historical reference dated 2006. Traditional home-kit reference; not a 2026/27 kit check.
A32: Cardiff City | B32: England | C32: EFL Championship | D32: 2 | E32: Single division | F32: 2026/27 | G32: Domestic | H32: First team | I32: Welsh club in the English league system. | J32: S02 | K32: https://www.efl.com/news/2026/august/22/sky-bet-championship-results--table---stats/ | L32: Blue | M32: White | N32: Both colours | O32: Historical kit reference | P32: https://www.rsssf.org/colours/england.html | Q32: Historical reference dated 2006. Traditional home-kit reference; not a 2026/27 kit check.
A33: Charlton Athletic | B33: England | C33: EFL Championship | D33: 2 | E33: Single division | F33: 2026/27 | G33: Domestic | H33: First team | J33: S02 | K33: https://www.efl.com/news/2026/august/22/sky-bet-championship-results--table---stats/ | L33: Red | M33: White | N33: Both colours | O33: Historical kit reference | P33: https://www.rsssf.org/colours/england.html | Q33: Historical reference dated 2006. Traditional home-kit reference; not a 2026/27 kit check.
A34: Derby County | B34: England | C34: EFL Championship | D34: 2 | E34: Single division | F34: 2026/27 | G34: Domestic | H34: First team | J34: S02 | K34: https://www.efl.com/news/2026/august/22/sky-bet-championship-results--table---stats/ | L34: White | M34: Black | N34: Both colours | O34: Historical kit reference | P34: https://www.rsssf.org/colours/england.html | Q34: Historical reference dated 2006. Traditional home-kit reference; not a 2026/27 kit check.
